Workbook
Name runtime_parser: meta!$B$7
Name runtime_dispatch: meta!$B$8
Name runtime_call: meta!$B$4
Name runtime_eval: meta!$B$9
Name runtime_eval_v2: meta!$B$9
Name runtime_split_args: meta!$B$10
Name runtime_typeof: meta!$B$11
Name runtime_wrap: meta!$B$12
Name runtime_error: meta!$B$13
Name runtime_unwrap: meta!$B$14
Name runtime_value_type: meta!$B$15
Name runtime_error_code: meta!$B$16
Name runtime_is_error: meta!$B$17

Sheet tests
A1: case | B1: expr | C1: actual | D1: expected | E1: pass
A2: Path basename | B2: path.basename("a/b/c.txt") | C2: =meta!B14(meta!B9(B2)) | D2: c.txt | E2: =IFERROR(C2=D2,FALSE)
A3: Join | B3: path.join("a","b","c") | C3: =meta!B14(meta!B9(B3)) | D3: a/b/c | E3: =IFERROR(C3=D3,FALSE)
A4: Math | B4: math.add3(1,2,3) | C4: =meta!B14(meta!B9(B4)) | D4: 6 | E4: =IFERROR(C4=D4,FALSE)
A5: Bool | B5: path.isAbsolute("/tmp") | C5: =meta!B14(meta!B9(B5)) | D5: TRUE | E5: =IFERROR(C5=D5,FALSE)
A6: Math mul3 | B6: math.mul3(2,3,4) | C6: =meta!B14(meta!B9(B6)) | D6: 24 | E6: =IFERROR(C6=D6,FALSE)
A7: Nested math | B7: math.add3(1, math.mul3(2,3,4), 5) | C7: =meta!B14(meta!B9(B7)) | D7: 30 | E7: =IFERROR(C7=D7,FALSE)
A8: Arity error | B8: path.basename() | C8: =meta!B14(meta!B9(B8)) | D8: #ERR: invalid arity | E8: =IFERROR(C8=D8,FALSE)
A9: Type error | B9: math.add3("a",2,3) | C9: =meta!B14(meta!B9(B9)) | D9: #ERR: invalid arg type | E9: =IFERROR(C9=D9,FALSE)
A10: Zero-arg function | B10: path.delimiter() | C10: =meta!B14(meta!B9(B10)) | D10: / | E10: =IFERROR(C10=D10,FALSE)
A11: Quoted comma | B11: path.join("a,b","c") | C11: =meta!B14(meta!B9(B11)) | D11: a,b/c | E11: =IFERROR(C11=D11,FALSE)
A12: Bad parse | B12: math.add3(1,2 | C12: =meta!B14(meta!B9(B12)) | D12: #ERR: bad parse | E12: =IFERROR(C12=D12,FALSE)
A13: Bad quote | B13: path.basename("a/b | C13: =meta!B14(meta!B9(B13)) | D13: #ERR: bad parse | E13: =IFERROR(C13=D13,FALSE)
A14: Unknown function | B14: foo.bar(1,2,3) | C14: =meta!B14(meta!B9(B14)) | D14: #ERR: unknown function | E14: =IFERROR(C14=D14,FALSE)
A15: Max depth guard | B15: math.add3(1,2,math.add3(1,2,math.add3(1,2,math.add3(1,2,math.add3(1,2,math.add3(1,2,math.add3(1,2,math.add3(1,2,math.add3(1,2,math.add3(1,2,math.add3(1,2,math.add3(1,2,math.add3(1,2,math.add3(1,2,math.add3(1,2,math.add3(1,2,math.add3(1,2,math.add3(1,2,math.add3(1,2,math.add3(1,2,math.add3(1,2,math.add3(1,2,math.add3(1,2,math.add3(1,2,math.add3(1,2,math.add3(1,2,math.add3(1,2,math.add3(1,2,math.add3(1,2,math.add3(1,2,math.add3(1,2,math.add3(1,2,math.add3(1,2,math.add3(1,2,math.add3(1,2,math.add3(1,2,math.add3(1,2,math.add3(1,2,math.add3(1,2,math.add3(1,2,math.add3(1,2,math.add3(1,2,math.add3(1,2,math.add3(1,2,math.add3(1,2,math.add3(1,2,math.add3(1,2,math.add3(1,2,math.add3(1,2,math.add3(1,2,math.add3(1,2,math.add3(1,2,math.add3(1,2,math.add3(1,2,math.add3(1,2,math.add3(1,2,math.add3(1,2,math.add3(1,2,math.add3(1,2,math.add3(1,2,math.add3(1,2,math.add3(1,2,math.add3(1,2,math.add3(1,2,math.add3(1,2,math.add3(1,2,3)))))))))))))))))))))))))))))))))))))))))))))))))))))))))))))))))) | C15: =meta!B14(meta!B9(B15)) | D15: #ERR: max depth | E15: =IFERROR(C15=D15,FALSE)
A16: Escaped comma | B16: path.join("a\,b","c") | C16: =meta!B14(meta!B9(B16)) | D16: a\,b/c | E16: =IFERROR(C16=D16,FALSE)
A17: Escaped quote | B17: path.basename("a/\"b.txt") | C17: =meta!B14(meta!B9(B17)) | D17: "b.txt | E17: =IFERROR(C17=D17,FALSE)
A18: Promise resolve | B18: promise.state(promise.resolve("ok")) | C18: =meta!B14(meta!B9(B18)) | D18: RESOLVED | E18: =IFERROR(C18=D18,FALSE)
A19: Promise reject | B19: promise.reject("fail") | C19: =meta!B14(meta!B9(B19)) | D19: #ERR: async rejected | E19: =IFERROR(C19=D19,FALSE)
... A23: Network fetch | B23: network.fetch("https://example.test/hello") | C23: =meta!B14(meta!B9(B23)) | D23: {"status":200,"body":"hello"} | E23: =IFERROR(C23=D23,FALSE)

Sheet runtime_summary
A1: gate | B1: evidence | C1: status
A2: Plan rows all DONE | B2: runtime_plan!C2:C10 | C2: =IF(COUNTIF(runtime_plan!C2:C10,"<>DONE")=0,"PASS","FAIL")
A3: E2E tests all pass | B3: tests!E2:E23 | C3: =IF(COUNTIF(tests!E2:E23,FALSE)=0,"PASS","FAIL")
A4: Typed values all pass | B4: runtime_values!I2:I23 | C4: =IF(COUNTIF(runtime_values!I2:I23,FALSE)=0,"PASS","FAIL")
A5: Runtime trace all pass | B5: runtime_trace!H2:H23 | C5: =IF(COUNTIF(runtime_trace!H2:H23,FALSE)=0,"PASS","FAIL")
A6: Frame ledger has no frame budget violation | B6: runtime_frames!M2:M23 | C6: =IF(COUNTIF(runtime_frames!M2:M23,"<0")=0,"PASS","FAIL")
A7: Module metadata present | B7: runtime_modules!A2:A10 | C7: =IF(COUNTA(runtime_modules!A2:A10)>=9,"PASS","FAIL")
A8: Error model present | B8: runtime_errors!A2:A8 | C8: =IF(COUNTA(runtime_errors!A2:A8)>=7,"PASS","FAIL")
A9: Async model present | B9: runtime_async!A2:A3 | C9: =IF(COUNTA(runtime_async!A2:A3)>=2,"PASS","FAIL")
A10: IO model present | B10: runtime_io!A2:A4 | C10: =IF(COUNTA(runtime_io!A2:A4)>=3,"PASS","FAIL")
A11: Overall | B11: =COUNTIF(C2:C10,"FAIL") | C11: =IF(B11=0,"PASS","FAIL")

Sheet functions
A1: module | B1: function | C1: implemented | D1: state | E1: min_arity | F1: max_arity | G1: arg_types
A2: path | B2: basename | C2: TRUE | D2: =LAMBDA(p, [ext], LET(parts, TEXTSPLIT(p, "/"), filtered, FILTER(parts, parts<>""), base, INDEX(filtered, ROWS(filtered), 1), IF(OR(ISOMITTED(ext), ext=""), base, IF(RIGHT(base, LEN(ext))=ext, LEFT(base, LEN(base)-LEN(ext)), base))) | E2: 1 | F2: 2 | G2: string,string
A3: path | B3: delimiter | C3: TRUE | D3: =LAMBDA([a1],"/") | E3: 0 | F3: 0
A4: path | B4: dirname | C4: TRUE | D4: =LAMBDA(p,LET(_p,p&"",_n,LEN(_p),IF(OR(_p="",_p="/"),"/",LET(_slash,IFERROR(LOOKUP(2,1/(MID(_p,SEQUENCE(_n),1)="/"),SEQUENCE(_n)),0),IF(_slash<=1,"/",LEFT(_p,_slash-1)))))) | E4: 1 | F4: 1 | G4: string
A5: path | B5: extname | C5: TRUE | D5: =LAMBDA(p,LET(_p,p&"",_n,LEN(_p),_slash,IFERROR(LOOKUP(2,1/(MID(_p,SEQUENCE(_n),1)="/"),SEQUENCE(_n)),0),_dot,IFERROR(LOOKUP(2,1/(MID(_p,SEQUENCE(_n),1)="."),SEQUENCE(_n)),0),IF(OR(_dot=0,_dot<=_slash),"",MID(_p,_dot,_n-_dot+1)))) | E5: 1 | F5: 1 | G5: string
A6: path | B6: format | C6: TRUE | D6: =LAMBDA(po,LET(r,IFERROR(po[root],""),d,IFERROR(po[dir],""),b,IFERROR(po[base],""),n,IFERROR(po[name],""),e,IFERROR(po[ext],""),f,IF(b="",n&e,b),IF(d="",r&f,IF(LEFT(d,1)="/",d&IF(RIGHT(d,1)="/","","/")&f,r&IF(RIGHT(r,1)="/","",IF(r="","","/"))&d&"/"&f)))) | E6: 1 | F6: 1 | G6: any
A7: path | B7: isAbsolute | C7: TRUE | D7: =LAMBDA(p, IF(LEN(p)=0, FALSE, LEFT(p,1)="/")) | E7: 1 | F7: 1 | G7: string
A8: path | B8: join | C8: TRUE | D8: =LAMBDA(p1,[p2],[p3],[p4],[p5],TEXTJOIN("/",TRUE,p1,p2,p3,p4,p5)) | E8: 1 | F8: 5 | G8: string,string,string,string,string
A9: path | B9: normalize | C9: TRUE | D9: =LAMBDA(p,LET(_p,p&"",_abs,LEFT(_p,1)="/",_parts,IFERROR(FILTER(TEXTSPLIT(_p,"/"),TEXTSPLIT(_p,"/")<>""),""),_joined,TEXTJOIN("/",TRUE,_parts),IF(_joined="",IF(_abs,"/","."),IF(_abs,"/"&_joined,_joined)))) | E9: 1 | F9: 1 | G9: string
A10: path | B10: parse | C10: TRUE | D10: =LAMBDA(p,LET(_p,p&"",_n,LEN(_p),_root,IF(LEFT(_p,1)="/","/",""),_slash,IFERROR(LOOKUP(2,1/(MID(_p,SEQUENCE(_n),1)="/"),SEQUENCE(_n)),0),_base,IF(OR(_p="",RIGHT(_p,1)="/"),"",RIGHT(_p,_n-_slash)),_dot,IFERROR(LOOKUP(2,1/(MID(_base,SEQUENCE(LEN(_base)),1)="."),SEQUENCE(LEN(_base))),0),_ext,IF(_dot=0,"",RIGHT(_base,LEN(_base)-_dot+1)),_name,IF(_ext="",_base,LEFT(_base,LEN(_base)-LEN(_ext))),_dir,IF(_slash=0,"",IF(_slash=1,"/",LEFT(_p,_slash-1))),HSTACK({"root","dir","base","ext","name"},{_root,_dir,_base,_ext,_name}))) | E10: 1 | F10: 1 | G10: string
A11: path | B11: relative | C11: TRUE | D11: =LAMBDA(from,to,LET(relative,IFERROR(TEXTAFTER(to,from&"/"),""),IF(relative="",IF(to=from,".",to),relative))) | E11: 2 | F11: 2 | G11: string,string
A12: url | B12: parse | C12: TRUE | D12: =LAMBDA(url,parseQueryString,slashesDenoteHost,LET(_parseQueryString,IFERROR(parseQueryString,FALSE),_slashesDenoteHost,IFERROR(slashesDenoteHost,FALSE),raw,IFERROR(url,""),clean,TRIM(raw),protoPos,IFERROR(FIND("://",clean),0),protocol,IF(protoPos=0,"",LEFT(clean,protoPos-1)&":"),rest,IF(protoPos=0,clean,MID(clean,protoPos+3,LEN(clean)-protoPos-2),hashPos,IFERROR(FIND("#",rest),0),hash,IF(hashPos=0,"",MID(rest,hashPos,LEN(rest)-hashPos+1)),withoutHash,IF(hashPos=0,rest,LEFT(rest,hashPos-1)),slashPos,IFERROR(FIND("/",withoutHash),0),authority,IF(slashPos=0,withoutHash,LEFT(withoutHash,slashPos-1)),pathAndQuery,IF(slashPos=0,"",MID(withoutHash,slashPos,LEN(withoutHash)-slashPos+1)),queryPos,IF(pathAndQuery="",0,IFERROR(FIND("?",pathAndQuery),0)),pathname,IF(slashPos=0,"",IF(queryPos=0,pathAndQuery,LEFT(pathAndQuery,queryPos-1))),query,IF(slashPos=0,"",IF(queryPos=0,"",MID(pathAndQuery,queryPos+1,LEN(pathAndQuery)-queryPos))),search,IF(query="","", "?"&query),atPos,IFERROR(FIND("@",authority),0),hostPort,IF(atPos=0,authority,RIGHT(authority,LEN(authority)-atPos)),colonPos,IFERROR(FIND(":",hostPort),0),hostname,IF(colonPos=0,hostPort,LEFT(hostPort,colonPos-1)),host,hostPort,port,IF(colonPos=0,"",MID(hostPort,colonPos+1,LEN(hostPort)-colonPos)),HSTACK({"protocol","slashes","auth","host","port","hostname","hash","search","query","pathname","path","href"},{protocol,protoPos>0,"",host,port,hostname,hash,search,query,pathname,pathname,clean}))) | E12: 1 | F12: 3 | G12: string,any,any
A13: url | B13: resolve | C13: TRUE | D13: =LAMBDA(source,relative,LET(_s,source&"",_r,relative&"",_scheme,ISNUMBER(SEARCH("://",_r)),IF(_scheme,_r,LET(_pos,IFERROR(SEARCH("://",_s),0),_after,IF(_pos=0,_s,MID(_s,_pos+3,LEN(_s))),_slash,IFERROR(SEARCH("/",_after),0),_origin,IF(_pos=0,"",LEFT(_s,_pos+2)&IF(_slash=0,_after,LEFT(_after,_slash-1))),IF(LEFT(_r,1)="/",_origin&_r,_origin&"/"&_r))))) | E13: 2 | F13: 2 | G13: string,string
A14: semver | B14: parse | C14: TRUE | D14: =LAMBDA(version,LET(raw,IFERROR(version,""),clean,TRIM(raw),noPrefix,IF(LEFT(clean,1)="v",RIGHT(clean,LEN(clean)-1),clean),noEq,IF(LEFT(noPrefix,1)="=",RIGHT(noPrefix,LEN(noPrefix)-1),noPrefix),compact,IFERROR(LEFT(noEq,FIND(" ",noEq)-1),noEq),withBuild,IFERROR(LEFT(compact,FIND("+",compact)-1),compact),build,IFERROR(TEXTAFTER(compact,"+"),""),main,IFERROR(LEFT(withBuild,FIND("-",withBuild)-1),withBuild),pre,IFERROR(TEXTAFTER(withBuild,"-"),""),parts,TEXTSPLIT(main,"."),major,IFERROR(--INDEX(parts,1),0),minor,IFERROR(--INDEX(parts,2),0),patch,IFERROR(--INDEX(parts,3),0),HSTACK({"major","minor","patch","prerelease","build","version"},{major,minor,patch,IF(pre="","",pre),IF(build="","",build),main})) | E14: 1 | F14: 1 | G14: string
A15: math | B15: abs | C15: TRUE | D15: =LAMBDA(x,IFERROR(ABS(x),0)) | E15: 1 | F15: 1 | G15: number
A16: math | B16: acos | C16: TRUE | D16: =LAMBDA(x,IFERROR(ACOS(x),0)) | E16: 1 | F16: 1 | G16: number
A17: math | B17: acosh | C17: TRUE | D17: =LAMBDA(x,IFERROR(ACOSH(x),0)) | E17: 1 | F17: 1 | G17: number
A18: math | B18: add2 | C18: TRUE | D18: =LAMBDA(a,b,a+b) | E18: 2 | F18: 2 | G18: number,number
A19: math | B19: add3 | C19: TRUE | D19: =LAMBDA(a,b,c,a+b+c) | E19: 3 | F19: 3 | G19: number,number,number
A20: math | B20: add4 | C20: TRUE | D20: =LAMBDA(a,b,c,d,a+b+c+d)
A21: math | B21: asin | C21: TRUE | D21: =LAMBDA(x,IFERROR(ASIN(x),0))
A22: math | B22: asinh | C22: TRUE | D22: =LAMBDA(x,IFERROR(ASINH(x),0))
A23: math | B23: atan | C23: TRUE | D23: =LAMBDA(x,IFERROR(ATAN(x),0))
A24: math | B24: atanh | C24: TRUE | D24: =LAMBDA(x,IFERROR(ATANH(x),0))
A25: math | B25: atan2 | C25: TRUE | D25: =LAMBDA(y,x,IFERROR(ATAN2(y,x),0))
A26: math | B26: cbrt | C26: TRUE | D26: =LAMBDA(x,IFERROR(SIGN(x)*ABS(x)^(1/3),0))
A27: math | B27: ceil | C27: TRUE | D27: =LAMBDA(x,IFERROR(ROUNDUP(x,0),0))
A28: math | B28: clamp | C28: TRUE | D28: =LAMBDA(v,lo,hi,IF(v<lo,lo,IF(v>hi,hi,v)))
A29: math | B29: cos | C29: TRUE | D29: =LAMBDA(x,IFERROR(COS(x),0))
A30: math | B30: cosh | C30: TRUE | D30: =LAMBDA(x,IFERROR(COSH(x),0))
A31: math | B31: degrees | C31: TRUE | D31: =LAMBDA(x,IFERROR(DEGREES(x),0))
A32: math | B32: div2 | C32: TRUE | D32: =LAMBDA(a,b,IFERROR(a/b,0))
A33: math | B33: div3 | C33: TRUE | D33: =LAMBDA(a,b,c,IFERROR(a/(b*c),0))
A34: math | B34: exp | C34: TRUE | D34: =LAMBDA(x,IFERROR(EXP(x),0))
A35: math | B35: expm1 | C35: TRUE | D35: =LAMBDA(x,IFERROR(EXP(x)-1,0))
A36: math | B36: floor | C36: TRUE | D36: =LAMBDA(x,IFERROR(ROUNDDOWN(x,0),0))
A37: math | B37: gcd | C37: TRUE | D37: =LAMBDA(a,b,GCD(ROUND(a,0),ROUND(b,0)))
A38: math | B38: hypot | C38: TRUE | D38: =LAMBDA(a,b,SQRT(a*a+b*b))
A39: math | B39: is_integer | C39: TRUE | D39: =LAMBDA(x,AND(ISNUMBER(x),INT(x)=x))
A40: math | B40: is_negative | C40: TRUE | D40: =LAMBDA(x,x<0)
...

Sheet meta
A1: key | B1: value
A2: module_count | B2: =COUNTA(runtime_modules!A2:A100)
A3: status | B3: interpreter_entrypoint_in_xlsx_typed_e2e
A4: runtime_call | B4: =LAMBDA(module,function,[a1],[a2],[a3],[a4],[a5],[a6],[a7],[a8],[n],LET(_key,module&"|"&function,_col,functions!$A$2:$A$250&"|"&functions!$B$2:$B$250,_row,IFERROR(XMATCH(_key,_col,0),0),_fn,IF(_row=0,NA(),INDEX(functions!$D$2:$D$250,_row)),_min,IFERROR(--INDEX(functions!$E$2:$E$250,_row),0),_maxRaw,IF(_row=0,"",INDEX(functions!$F$2:$F$250,_row)),_max,IF(_maxRaw="",-1,--_maxRaw),_types,IF(_row=0,"",IFERROR(INDEX(functions!$G$2:$G$250,_row),"")),_args,HSTACK(a1,a2,a3,a4,a5,a6,a7,a8),_spec,IF(_types="",{},TEXTSPLIT(_types,",")),_passArity,IF(_row=0,TRUE(),IF(AND(_min<=n,OR(_max<0,n<=_max)),TRUE(),FALSE())),_passType,IF(OR(_row=0,n=0,_types=""),TRUE(),IFERROR(AND(MAP(SEQUENCE(n),LAMBDA(i,LET(_s,TRIM(INDEX(_spec,i)),_a,INDEX(_args,i),IF(_s="",TRUE(),IF(_s="any",TRUE(),IF(_s="number",ISNUMBER(_a),IF(_s="string",ISTEXT(_a),IF(_s="boolean",OR(_a=TRUE(),_a=FALSE()),TRUE())))))))),FALSE())),_argErr,IF(n=0,"",IFERROR(INDEX(FILTER(_args,MAP(_args,LAMBDA(x,LEFT((x&""),5)="#ERR:"))),1),"")),_call,IF(n=0,_fn(),IF(n=1,_fn(a1),IF(n=2,_fn(a1,a2),IF(n=3,_fn(a1,a2,a3),IF(n=4,_fn(a1,a2,a3,a4),IF(n=5,_fn(a1,a2,a3,a4,a5),IF(n=6,_fn(a1,a2,a3,a4,a5,a6),IF(n=7,_fn(a1,a2,a3,a4,a5,a6,a7),IF(n=8,_fn(a1,a2,a3,a4,a5,a6,a7,a8),_fn())))))))),IF(_argErr<>"",B12(_argErr),IF(_row=0,B13("unknown function","No such function: "&module&"."&function),IF(NOT(_passArity),B13("invalid arity","Expected "&_min&".."&_max&" arguments, got "&n),IF(NOT(_passType),B13("invalid arg type","Type check failed for "&module&"."&function),B12(_call)))))))
A5: runtime_eval | B5: =B9(A5,0)
A6: runtime_plan_sheet | B6: runtime_plan
A7: runtime_parser | B7: =LAMBDA(expr,[depth],LET( _src,TRIM(expr), _depth,IF(depth="",0,depth), _len,LEN(_src), _seq,IF(_len=0,{},SEQUENCE(_len)), _chars,IF(_len=0,"",MID(_src,_seq,1)), _esc,IF(_len=0,{},SCAN(0,_seq,LAMBDA(a,i,LET(_ch,MID(_src,i,1),IF(a=1,0,IF(_ch=CHAR(92),1,0))))), _quote,IF(_len=0,{},SCAN(0,_seq,LAMBDA(a,i,LET(_ch,MID(_src,i,1),_e,INDEX(_esc,i),IF(_e,a,IF(_ch=CHAR(34),1-a,a))))), _badEscape,IF(_len=0,FALSE,INDEX(_esc,_len)=1), _level,IF(_len=0,{},SCAN(0,_seq,LAMBDA(a,i,LET(_ch,MID(_src,i,1),_e,INDEX(_esc,i),_q,INDEX(_quote,i),IF(_q,a,IF(_e,a,IF(_ch="(",a+1,IF(_ch=")",a-1,a))))))), _open,IFERROR(FIND("(",_src),0), _close,IF(_open=0,0,IFERROR(MIN(FILTER(_seq,(_chars=")")*(_level=0)*(_seq>_open)),0)), IF( OR(_depth>64,_len=0,_badEscape,_open=0,_close=0,INDEX(_level,_len)<>0,INDEX(_quote,_len)<>0), IF(_depth>64,"#ERR: max depth",HSTACK("#ERR","#ERR: bad parse",0,"","","","","","","","")), LET( _head,LEFT(_src,_open-1), _dot,IFERROR(FIND(".",_head),0), IF(_dot=0,HSTACK("#ERR","#ERR: bad parse",0,"","","","","","","",""), LET( _module,LEFT(_head,_dot-1), _fnName,MID(_head,_dot+1,LEN(_head)-_dot), _body,TRIM(MID(_src,_open+1,_close-_open-1)), _parts,IF(_body="",{},IFERROR(B10(_body),{})), _vals,IFERROR(MAP(_parts, LAMBDA(v, LET( _v,TRIM(v), IF(_v="",, IF( AND(LEFT(_v,1)=CHAR(34),RIGHT(_v,1)=CHAR(34),LEN(_v)>=2), SUBSTITUTE(SUBSTITUTE(MID(_v,2,LEN(_v)-2),CHAR(92)&CHAR(34),CHAR(34)),CHAR(92)&CHAR(92),CHAR(92)), IFERROR(IFERROR(--_v, IF(LOWER(_v)="true",TRUE(),IF(LOWER(_v)="false",FALSE(), LET( _dotArg,IFERROR(FIND(".",_v),0), _openArg,IFERROR(FIND("(",_v),0), _closeArg,IFERROR(FIND(")",_v,_openArg+1),0), IF(AND(_dotArg>0,_openArg>_dotArg,_closeArg=LEN(_v)),B14(B9(_v,_depth+1)),_v) )) ) )) )),{}), _n,IF(_body="",0,COUNTA(_vals)), _a1,IF(_n>=1,INDEX(_vals,1),), _a2,IF(_n>=2,INDEX(_vals,2),), _a3,IF(_n>=3,INDEX(_vals,3),), _a4,IF(_n>=4,INDEX(_vals,4),), _a5,IF(_n>=5,INDEX(_vals,5),), _a6,IF(_n>=6,INDEX(_vals,6),), _a7,IF(_n>=7,INDEX(_vals,7),), _a8,IF(_n>=8,INDEX(_vals,8),), HSTACK(_module,_fnName,_n,_a1,_a2,_a3,_a4,_a5,_a6,_a7,_a8) ) ) ) ) ))
A8: runtime_dispatch | B8: =LAMBDA(parsed,[depth],LET(_module,INDEX(parsed,1),_fnName,INDEX(parsed,2),_n,INDEX(parsed,3),_a1,INDEX(parsed,4),_a2,INDEX(parsed,5),_a3,INDEX(parsed,6),_a4,INDEX(parsed,7),_a5,INDEX(parsed,8),_a6,INDEX(parsed,9),_a7,INDEX(parsed,10),_a8,INDEX(parsed,11),IF(_module="#ERR",B13("bad parse"),B4(_module,_fnName,IF(_n>=1,_a1,""),IF(_n>=2,_a2,""),IF(_n>=3,_a3,""),IF(_n>=4,_a4,""),IF(_n>=5,_a5,""),IF(_n>=6,_a6,""),IF(_n>=7,_a7,""),IF(_n>=8,_a8,""),_n))))
A9: runtime_eval_v2 | B9: =LAMBDA(expr,[depth],LET(_d,IF(depth="",0,depth),_p,B7(expr,_d),IF(INDEX(_p,1)="#ERR",B13(SUBSTITUTE(INDEX(_p,2),"#ERR: ","")),B8(_p,_d))))
A10: runtime_split_args | B10: =LAMBDA(body,LET(_body,TRIM(body),_n,LEN(_body),IF(_n=0,{},LET(_seq,SEQUENCE(_n),_chars,MID(_body,_seq,1),_esc,SCAN(0,_seq,LAMBDA(a,i,LET(_ch,INDEX(_chars,i),IF(a=1,0,IF(_ch=CHAR(92),1,0)))),_quote,SCAN(0,_seq,LAMBDA(a,i,LET(_ch,INDEX(_chars,i),_e,INDEX(_esc,i),IF(_e,a,IF(_ch=CHAR(34),1-a,a)))),_badEscape,IF(_n=0,FALSE,INDEX(_esc,_n)=1),IF(_badEscape,{"#ERR","#ERR: bad parse"},LET(_depth,SCAN(0,_seq,LAMBDA(a,i,LET(_ch,INDEX(_chars,i),_e,INDEX(_esc,i),_q,INDEX(_quote,i),IF(_q,a,IF(_e,a,IF(_ch="(",a+1,IF(_ch=")",a-1,a)))))),_is_sep,(_chars=",")*(_depth=0)*(_quote=0),_marked,TEXTJOIN("",,MAP(_seq,LAMBDA(i,IF(INDEX(_is_sep,i),CHAR(31),MID(_body,i,1)))),_parts,MAP(TEXTSPLIT(_marked,CHAR(31),,,TRUE),LAMBDA(p,TRIM(p))),FILTER(_parts,_parts<>"")))))
A11: runtime_typeof | B11: =LAMBDA(v,LET(_s,(v&""),IF(LEFT(_s,5)="#ERR:","error",IF(ISNUMBER(v),"number",IF(OR(_s="TRUE",_s="FALSE"),"boolean",IF(_s="#NULL","null","string"))))))
A12: runtime_wrap | B12: =LAMBDA(v,LET(_t,B11(v),_s,(v&""),SWITCH(_t,"number","N|"&_s,"boolean","B|"&_s,"null","Z|","error","E|"&_s&"|"&_s,"S|"&SUBSTITUTE(_s,"|","||"))))
A13: runtime_error | B13: =LAMBDA(code,[message],LET(_c,IF(LEFT(code,5)="#ERR:",code,"#ERR: "&code),"E|"&_c&"|"&IF(ISOMITTED(message),_c,message)))
A14: runtime_unwrap | B14: =LAMBDA(env,LET(_s,(env&""),_tag,LEFT(_s,1),_body,MID(_s,3,LEN(_s)-2),SWITCH(_tag,"N",--_body,"B",_body="TRUE","Z","","E",IFERROR(TEXTBEFORE(_body,"|"),_body),SUBSTITUTE(_body,"||","|"))))
A15: runtime_value_type | B15: =LAMBDA(env,SWITCH(LEFT((env&""),1),"N","number","B","boolean","Z","null","E","error","S","string","unknown"))
A16: runtime_error_code | B16: =LAMBDA(env,LET(_s,(env&""),IF(LEFT(_s,1)<>"E","",IFERROR(TEXTBEFORE(MID(_s,3,999),"|"),MID(_s,3,999)))))
A17: runtime_is_error | B17: =LAMBDA(env,LEFT((env&""),1)="E")

Sheet runtime_plan
A1: section | B1: item | C1: status | D1: details
A2: 1 | B2: In-workbook parser for function-call expressions | C2: DONE | D2: Implemented nested-aware parser: depth-tracking matching paren, top-level arg split, nested call token evaluation.
A3: 1 | B3: Runtime dispatch | C3: DONE | D3: Added arity/type validation path via functions metadata (min/max arity + basic type checks) and runtime_call error codes.
A4: 2 | B4: Call stack / frame model | C4: DONE | D4: runtime_frames provides explicit workbook-native frame ledger with depth/budget/status over each e2e case; recursive nested calls execute through runtime_eval.
A5: 2 | B5: Memory/context model | C5: DONE | D5: runtime_values plus meta!B11:B17 implement tagged typed value envelopes, unwrap/type/error helpers, and per-test value audit.
A6: 2 | B6: Error semantics | C6: DONE | D6: runtime_errors and meta!B13/B16/B17 standardize #ERR envelopes and propagation through parser/dispatch/runtime_run.
A7: 3 | B7: Bun API modules expansion | C7: DONE | D7: runtime_modules describes supported modules; functions includes path/math/url/semver/date plus promise/fs/process/network pure-sheet simulations.
A8: 3 | B8: Promise/async contract | C8: DONE | D8: runtime_async and promise.* functions model RESOLVED/REJECTED state as pure sheet strings/envelopes.
A9: 3 | B9: IO boundary model | C9: DONE | D9: runtime_io fixtures and fs/process/network functions simulate IO without external runtime calls.
A10: 4 | B10: Verification matrix | C10: DONE | D10: tests + runtime_trace now provide workbook-native e2e verification matrix.

Sheet runtime_trace
A1: step | B1: expr | C1: parsed | D1: typed_result | E1: result | F1: status | G1: expected | H1: pass
A2: =IF(tests!A2="","",ROW()-1) | B2: =tests!B2 | C2: =IF(B2="","",runtime_step!G2) | D2: =IF(B2="","",runtime_run!B2) | E2: =IF(B2="","",runtime_run!C2) | F2: =IF(B2="","",runtime_run!D2) | G2: =IF(B2="","",tests!D2) | H2: =IF(B2="","",IFERROR(E2=G2,FALSE))
A3: =IF(tests!A3="","",ROW()-1) | B3: =tests!B3 | C3: =IF(B3="","",runtime_step!G3) | D3: =IF(B3="","",runtime_run!B3) | E3: =IF(B3="","",runtime_run!C3) | F3: =IF(B3="","",runtime_run!D3) | G3: =IF(B3="","",tests!D3) | H3: =IF(B3="","",IFERROR(E3=G3,FALSE))
A4: =IF(tests!A4="","",ROW()-1) | B4: =tests!B4 | C4: =IF(B4="","",runtime_step!G4) | D4: =IF(B4="","",runtime_run!B4) | E4: =IF(B4="","",runtime_run!C4) | F4: =IF(B4="","",runtime_run!D4) | G4: =IF(B4="","",tests!D4) | H4: =IF(B4="","",IFERROR(E4=G4,FALSE))
A5: =IF(tests!A5="","",ROW()-1) | B5: =tests!B5 | C5: =IF(B5="","",runtime_step!G5) | D5: =IF(B5="","",runtime_run!B5) | E5: =IF(B5="","",runtime_run!C5) | F5: =IF(B5="","",runtime_run!D5) | G5: =IF(B5="","",tests!D5) | H5: =IF(B5="","",IFERROR(E5=G5,FALSE))
A6: =IF(tests!A6="","",ROW()-1) | B6: =tests!B6 | C6: =IF(B6="","",runtime_step!G6) | D6: =IF(B6="","",runtime_run!B6) | E6: =IF(B6="","",runtime_run!C6) | F6: =IF(B6="","",runtime_run!D6) | G6: =IF(B6="","",tests!D6) | H6: =IF(B6="","",IFERROR(E6=G6,FALSE))
A7: =IF(tests!A7="","",ROW()-1) | B7: =tests!B7 | C7: =IF(B7="","",runtime_step!G7) | D7: =IF(B7="","",runtime_run!B7) | E7: =IF(B7="","",runtime_run!C7) | F7: =IF(B7="","",runtime_run!D7) | G7: =IF(B7="","",tests!D7) | H7: =IF(B7="","",IFERROR(E7=G7,FALSE))
A8: =IF(tests!A8="","",ROW()-1) | B8: =tests!B8 | C8: =IF(B8="","",runtime_step!G8) | D8: =IF(B8="","",runtime_run!B8) | E8: =IF(B8="","",runtime_run!C8) | F8: =IF(B8="","",runtime_run!D8) | G8: =IF(B8="","",tests!D8) | H8: =IF(B8="","",IFERROR(E8=G8,FALSE))
A9: =IF(tests!A9="","",ROW()-1) | B9: =tests!B9 | C9: =IF(B9="","",runtime_step!G9) | D9: =IF(B9="","",runtime_run!B9) | E9: =IF(B9="","",runtime_run!C9) | F9: =IF(B9="","",runtime_run!D9) | G9: =IF(B9="","",tests!D9) | H9: =IF(B9="","",IFERROR(E9=G9,FALSE))
A10: =IF(tests!A10="","",ROW()-1) | B10: =tests!B10 | C10: =IF(B10="","",runtime_step!G10) | D10: =IF(B10="","",runtime_run!B10) | E10: =IF(B10="","",runtime_run!C10) | F10: =IF(B10="","",runtime_run!D10) | G10: =IF(B10="","",tests!D10) | H10: =IF(B10="","",IFERROR(E10=G10,FALSE))
A11: =IF(tests!A11="","",ROW()-1) | B11: =tests!B11 | C11: =IF(B11="","",runtime_step!G11) | D11: =IF(B11="","",runtime_run!B11) | E11: =IF(B11="","",runtime_run!C11) | F11: =IF(B11="","",runtime_run!D11) | G11: =IF(B11="","",tests!D11) | H11: =IF(B11="","",IFERROR(E11=G11,FALSE))
A12: =IF(tests!A12="","",ROW()-1) | B12: =tests!B12 | C12: =IF(B12="","",runtime_step!G12) | D12: =IF(B12="","",runtime_run!B12) | E12: =IF(B12="","",runtime_run!C12) | F12: =IF(B12="","",runtime_run!D12) | G12: =IF(B12="","",tests!D12) | H12: =IF(B12="","",IFERROR(E12=G12,FALSE))
A13: =IF(tests!A13="","",ROW()-1) | B13: =tests!B13 | C13: =IF(B13="","",runtime_step!G13) | D13: =IF(B13="","",runtime_run!B13) | E13: =IF(B13="","",runtime_run!C13) | F13: =IF(B13="","",runtime_run!D13) | G13: =IF(B13="","",tests!D13) | H13: =IF(B13="","",IFERROR(E13=G13,FALSE))
... A23: =IF(tests!A23="","",ROW()-1) | B23: =tests!B23 | C23: =IF(B23="","",runtime_step!G23) | D23: =IF(B23="","",runtime_run!B23) | E23: =IF(B23="","",runtime_run!C23) | F23: =IF(B23="","",runtime_run!D23) | G23: =IF(B23="","",tests!D23) | H23: =IF(B23="","",IFERROR(E23=G23,FALSE))

Sheet runtime_step
A1: expr | B1: depth_estimate | C1: parsed_module | D1: parsed_fn | E1: arg_count | F1: parse_status | G1: raw_parse | H1: frame_budget_ok | I1: depth_gate
A2: =IF(tests!A2="","",tests!B2) | B2: =IF(A2="","",LEN(A2)-LEN(SUBSTITUTE(A2,"(",""))) | C2: =IF(A2="","",INDEX(meta!B7(A2),1)) | D2: =IF(A2="","",INDEX(meta!B7(A2),2)) | E2: =IF(A2="","",IFERROR(INDEX(meta!B7(A2),3),"")) | F2: =IF(A2="","",IF(LEFT((INDEX(meta!B7(A2),1)&""),1)="#","ERR","OK")) | G2: =IF(A2="","",meta!B7(A2)) | H2: =IF(A2="","",IF(B2<=64,TRUE(),FALSE())) | I2: =IF(A2="","",IF(B2<=64,"ok","#ERR: max depth"))
A3: =IF(tests!A3="","",tests!B3) | B3: =IF(A3="","",LEN(A3)-LEN(SUBSTITUTE(A3,"(",""))) | C3: =IF(A3="","",INDEX(meta!B7(A3),1)) | D3: =IF(A3="","",INDEX(meta!B7(A3),2)) | E3: =IF(A3="","",IFERROR(INDEX(meta!B7(A3),3),"")) | F3: =IF(A3="","",IF(LEFT((INDEX(meta!B7(A3),1)&""),1)="#","ERR","OK")) | G3: =IF(A3="","",meta!B7(A3)) | H3: =IF(A3="","",IF(B3<=64,TRUE(),FALSE())) | I3: =IF(A3="","",IF(B3<=64,"ok","#ERR: max depth"))
A4: =IF(tests!A4="","",tests!B4) | B4: =IF(A4="","",LEN(A4)-LEN(SUBSTITUTE(A4,"(",""))) | C4: =IF(A4="","",INDEX(meta!B7(A4),1)) | D4: =IF(A4="","",INDEX(meta!B7(A4),2)) | E4: =IF(A4="","",IFERROR(INDEX(meta!B7(A4),3),"")) | F4: =IF(A4="","",IF(LEFT((INDEX(meta!B7(A4),1)&""),1)="#","ERR","OK")) | G4: =IF(A4="","",meta!B7(A4)) | H4: =IF(A4="","",IF(B4<=64,TRUE(),FALSE())) | I4: =IF(A4="","",IF(B4<=64,"ok","#ERR: max depth"))
A5: =IF(tests!A5="","",tests!B5) | B5: =IF(A5="","",LEN(A5)-LEN(SUBSTITUTE(A5,"(",""))) | C5: =IF(A5="","",INDEX(meta!B7(A5),1)) | D5: =IF(A5="","",INDEX(meta!B7(A5),2)) | E5: =IF(A5="","",IFERROR(INDEX(meta!B7(A5),3),"")) | F5: =IF(A5="","",IF(LEFT((INDEX(meta!B7(A5),1)&""),1)="#","ERR","OK")) | G5: =IF(A5="","",meta!B7(A5)) | H5: =IF(A5="","",IF(B5<=64,TRUE(),FALSE())) | I5: =IF(A5="","",IF(B5<=64,"ok","#ERR: max depth"))
A6: =IF(tests!A6="","",tests!B6) | B6: =IF(A6="","",LEN(A6)-LEN(SUBSTITUTE(A6,"(",""))) | C6: =IF(A6="","",INDEX(meta!B7(A6),1)) | D6: =IF(A6="","",INDEX(meta!B7(A6),2)) | E6: =IF(A6="","",IFERROR(INDEX(meta!B7(A6),3),"")) | F6: =IF(A6="","",IF(LEFT((INDEX(meta!B7(A6),1)&""),1)="#","ERR","OK")) | G6: =IF(A6="","",meta!B7(A6)) | H6: =IF(A6="","",IF(B6<=64,TRUE(),FALSE())) | I6: =IF(A6="","",IF(B6<=64,"ok","#ERR: max depth"))
A7: =IF(tests!A7="","",tests!B7) | B7: =IF(A7="","",LEN(A7)-LEN(SUBSTITUTE(A7,"(",""))) | C7: =IF(A7="","",INDEX(meta!B7(A7),1)) | D7: =IF(A7="","",INDEX(meta!B7(A7),2)) | E7: =IF(A7="","",IFERROR(INDEX(meta!B7(A7),3),"")) | F7: =IF(A7="","",IF(LEFT((INDEX(meta!B7(A7),1)&""),1)="#","ERR","OK")) | G7: =IF(A7="","",meta!B7(A7)) | H7: =IF(A7="","",IF(B7<=64,TRUE(),FALSE())) | I7: =IF(A7="","",IF(B7<=64,"ok","#ERR: max depth"))
A8: =IF(tests!A8="","",tests!B8) | B8: =IF(A8="","",LEN(A8)-LEN(SUBSTITUTE(A8,"(",""))) | C8: =IF(A8="","",INDEX(meta!B7(A8),1)) | D8: =IF(A8="","",INDEX(meta!B7(A8),2)) | E8: =IF(A8="","",IFERROR(INDEX(meta!B7(A8),3),"")) | F8: =IF(A8="","",IF(LEFT((INDEX(meta!B7(A8),1)&""),1)="#","ERR","OK")) | G8: =IF(A8="","",meta!B7(A8)) | H8: =IF(A8="","",IF(B8<=64,TRUE(),FALSE())) | I8: =IF(A8="","",IF(B8<=64,"ok","#ERR: max depth"))
A9: =IF(tests!A9="","",tests!B9) | B9: =IF(A9="","",LEN(A9)-LEN(SUBSTITUTE(A9,"(",""))) | C9: =IF(A9="","",INDEX(meta!B7(A9),1)) | D9: =IF(A9="","",INDEX(meta!B7(A9),2)) | E9: =IF(A9="","",IFERROR(INDEX(meta!B7(A9),3),"")) | F9: =IF(A9="","",IF(LEFT((INDEX(meta!B7(A9),1)&""),1)="#","ERR","OK")) | G9: =IF(A9="","",meta!B7(A9)) | H9: =IF(A9="","",IF(B9<=64,TRUE(),FALSE())) | I9: =IF(A9="","",IF(B9<=64,"ok","#ERR: max depth"))
A10: =IF(tests!A10="","",tests!B10) | B10: =IF(A10="","",LEN(A10)-LEN(SUBSTITUTE(A10,"(",""))) | C10: =IF(A10="","",INDEX(meta!B7(A10),1)) | D10: =IF(A10="","",INDEX(meta!B7(A10),2)) | E10: =IF(A10="","",IFERROR(INDEX(meta!B7(A10),3),"")) | F10: =IF(A10="","",IF(LEFT((INDEX(meta!B7(A10),1)&""),1)="#","ERR","OK")) | G10: =IF(A10="","",meta!B7(A10)) | H10: =IF(A10="","",IF(B10<=64,TRUE(),FALSE())) | I10: =IF(A10="","",IF(B10<=64,"ok","#ERR: max depth"))
A11: =IF(tests!A11="","",tests!B11) | B11: =IF(A11="","",LEN(A11)-LEN(SUBSTITUTE(A11,"(",""))) | C11: =IF(A11="","",INDEX(meta!B7(A11),1)) | D11: =IF(A11="","",INDEX(meta!B7(A11),2)) | E11: =IF(A11="","",IFERROR(INDEX(meta!B7(A11),3),"")) | F11: =IF(A11="","",IF(LEFT((INDEX(meta!B7(A11),1)&""),1)="#","ERR","OK")) | G11: =IF(A11="","",meta!B7(A11)) | H11: =IF(A11="","",IF(B11<=64,TRUE(),FALSE())) | I11: =IF(A11="","",IF(B11<=64,"ok","#ERR: max depth"))
A12: =IF(tests!A12="","",tests!B12) | B12: =IF(A12="","",LEN(A12)-LEN(SUBSTITUTE(A12,"(",""))) | C12: =IF(A12="","",INDEX(meta!B7(A12),1)) | D12: =IF(A12="","",INDEX(meta!B7(A12),2)) | E12: =IF(A12="","",IFERROR(INDEX(meta!B7(A12),3),"")) | F12: =IF(A12="","",IF(LEFT((INDEX(meta!B7(A12),1)&""),1)="#","ERR","OK")) | G12: =IF(A12="","",meta!B7(A12)) | H12: =IF(A12="","",IF(B12<=64,TRUE(),FALSE())) | I12: =IF(A12="","",IF(B12<=64,"ok","#ERR: max depth"))
A13: =IF(tests!A13="","",tests!B13) | B13: =IF(A13="","",LEN(A13)-LEN(SUBSTITUTE(A13,"(",""))) | C13: =IF(A13="","",INDEX(meta!B7(A13),1)) | D13: =IF(A13="","",INDEX(meta!B7(A13),2)) | E13: =IF(A13="","",IFERROR(INDEX(meta!B7(A13),3),"")) | F13: =IF(A13="","",IF(LEFT((INDEX(meta!B7(A13),1)&""),1)="#","ERR","OK")) | G13: =IF(A13="","",meta!B7(A13)) | H13: =IF(A13="","",IF(B13<=64,TRUE(),FALSE())) | I13: =IF(A13="","",IF(B13<=64,"ok","#ERR: max depth"))
... A23: =IF(tests!A23="","",tests!B23) | B23: =IF(A23="","",LEN(A23)-LEN(SUBSTITUTE(A23,"(",""))) | C23: =IF(A23="","",INDEX(meta!B7(A23),1)) | D23: =IF(A23="","",INDEX(meta!B7(A23),2)) | E23: =IF(A23="","",IFERROR(INDEX(meta!B7(A23),3),"")) | F23: =IF(A23="","",IF(LEFT((INDEX(meta!B7(A23),1)&""),1)="#","ERR","OK")) | G23: =IF(A23="","",meta!B7(A23)) | H23: =IF(A23="","",IF(B23<=64,TRUE(),FALSE())) | I23: =IF(A23="","",IF(B23<=64,"ok","#ERR: max depth"))

Sheet runtime_run
A1: expr | B1: typed_result | C1: result | D1: status | E1: expected | F1: pass
A2: =IF(tests!A2="","",tests!B2) | B2: =IF(A2="","",meta!B9(A2)) | C2: =IF(A2="","",meta!B14(B2)) | D2: =IF(A2="","",IF(meta!B17(B2),"ERR","OK")) | E2: =IF(A2="","",tests!D2) | F2: =IF(A2="","",IFERROR(C2=E2,FALSE))
A3: =IF(tests!A3="","",tests!B3) | B3: =IF(A3="","",meta!B9(A3)) | C3: =IF(A3="","",meta!B14(B3)) | D3: =IF(A3="","",IF(meta!B17(B3),"ERR","OK")) | E3: =IF(A3="","",tests!D3) | F3: =IF(A3="","",IFERROR(C3=E3,FALSE))
A4: =IF(tests!A4="","",tests!B4) | B4: =IF(A4="","",meta!B9(A4)) | C4: =IF(A4="","",meta!B14(B4)) | D4: =IF(A4="","",IF(meta!B17(B4),"ERR","OK")) | E4: =IF(A4="","",tests!D4) | F4: =IF(A4="","",IFERROR(C4=E4,FALSE))
A5: =IF(tests!A5="","",tests!B5) | B5: =IF(A5="","",meta!B9(A5)) | C5: =IF(A5="","",meta!B14(B5)) | D5: =IF(A5="","",IF(meta!B17(B5),"ERR","OK")) | E5: =IF(A5="","",tests!D5) | F5: =IF(A5="","",IFERROR(C5=E5,FALSE))
A6: =IF(tests!A6="","",tests!B6) | B6: =IF(A6="","",meta!B9(A6)) | C6: =IF(A6="","",meta!B14(B6)) | D6: =IF(A6="","",IF(meta!B17(B6),"ERR","OK")) | E6: =IF(A6="","",tests!D6) | F6: =IF(A6="","",IFERROR(C6=E6,FALSE))
A7: =IF(tests!A7="","",tests!B7) | B7: =IF(A7="","",meta!B9(A7)) | C7: =IF(A7="","",meta!B14(B7)) | D7: =IF(A7="","",IF(meta!B17(B7),"ERR","OK")) | E7: =IF(A7="","",tests!D7) | F7: =IF(A7="","",IFERROR(C7=E7,FALSE))
A8: =IF(tests!A8="","",tests!B8) | B8: =IF(A8="","",meta!B9(A8)) | C8: =IF(A8="","",meta!B14(B8)) | D8: =IF(A8="","",IF(meta!B17(B8),"ERR","OK")) | E8: =IF(A8="","",tests!D8) | F8: =IF(A8="","",IFERROR(C8=E8,FALSE))
A9: =IF(tests!A9="","",tests!B9) | B9: =IF(A9="","",meta!B9(A9)) | C9: =IF(A9="","",meta!B14(B9)) | D9: =IF(A9="","",IF(meta!B17(B9),"ERR","OK")) | E9: =IF(A9="","",tests!D9) | F9: =IF(A9="","",IFERROR(C9=E9,FALSE))
A10: =IF(tests!A10="","",tests!B10) | B10: =IF(A10="","",meta!B9(A10)) | C10: =IF(A10="","",meta!B14(B10)) | D10: =IF(A10="","",IF(meta!B17(B10),"ERR","OK")) | E10: =IF(A10="","",tests!D10) | F10: =IF(A10="","",IFERROR(C10=E10,FALSE))
A11: =IF(tests!A11="","",tests!B11) | B11: =IF(A11="","",meta!B9(A11)) | C11: =IF(A11="","",meta!B14(B11)) | D11: =IF(A11="","",IF(meta!B17(B11),"ERR","OK")) | E11: =IF(A11="","",tests!D11) | F11: =IF(A11="","",IFERROR(C11=E11,FALSE))
A12: =IF(tests!A12="","",tests!B12) | B12: =IF(A12="","",meta!B9(A12)) | C12: =IF(A12="","",meta!B14(B12)) | D12: =IF(A12="","",IF(meta!B17(B12),"ERR","OK")) | E12: =IF(A12="","",tests!D12) | F12: =IF(A12="","",IFERROR(C12=E12,FALSE))
A13: =IF(tests!A13="","",tests!B13) | B13: =IF(A13="","",meta!B9(A13)) | C13: =IF(A13="","",meta!B14(B13)) | D13: =IF(A13="","",IF(meta!B17(B13),"ERR","OK")) | E13: =IF(A13="","",tests!D13) | F13: =IF(A13="","",IFERROR(C13=E13,FALSE))
... A23: =IF(tests!A23="","",tests!B23) | B23: =IF(A23="","",meta!B9(A23)) | C23: =IF(A23="","",meta!B14(B23)) | D23: =IF(A23="","",IF(meta!B17(B23),"ERR","OK")) | E23: =IF(A23="","",tests!D23) | F23: =IF(A23="","",IFERROR(C23=E23,FALSE))

Sheet runtime_modules
A1: module | B1: kind | C1: surface | D1: aliases | E1: compat | F1: io_policy | G1: status
A2: path | B2: sync | C2: path operations | D2: node:path | E2: node-compatible | F2: pure | G2: implemented
A3: math | B3: sync | C3: numeric helpers | D3: Math subset | E3: workbook-native | F3: pure | G3: implemented
A4: url | B4: sync | C4: URL parsing/resolution | D4: node:url | E4: partial | F4: pure | G4: implemented
A5: semver | B5: sync | C5: version parsing | D5: bun semver subset | E5: partial | F5: pure | G5: implemented
A6: date | B6: sync | C6: date helpers | D6: Date subset | E6: partial | F6: pure | G6: implemented
A7: promise | B7: async-sim | C7: promise state envelope | D7: Promise subset | E7: simulated | F7: state-table | G7: implemented
A8: fs | B8: io-sim | C8: file reads | D8: Bun.file/fs subset | E8: simulated | F8: runtime_io lookup | G8: implemented
A9: process | B9: io-sim | C9: process state | D9: process subset | E9: simulated | F9: runtime_io lookup | G9: implemented
A10: network | B10: io-sim | C10: fetch response | D10: fetch subset | E10: simulated | F10: runtime_io lookup | G10: implemented

Sheet runtime_errors
A1: code | B1: envelope | C1: stage | D1: terminal | E1: meaning
A2: #ERR: bad parse | B2: =meta!B13("bad parse") | C2: parse | D2: TRUE | E2: Expression cannot be parsed.
A3: #ERR: max depth | B3: =meta!B13("max depth") | C3: parse | D3: TRUE | E3: Depth guard exceeded.
A4: #ERR: unknown function | B4: =meta!B13("unknown function") | C4: dispatch | D4: TRUE | E4: Module/function is absent from functions table.
A5: #ERR: invalid arity | B5: =meta!B13("invalid arity") | C5: dispatch | D5: TRUE | E5: Argument count is outside min/max metadata.
A6: #ERR: invalid arg type | B6: =meta!B13("invalid arg type") | C6: dispatch | D6: TRUE | E6: Runtime argument type does not match metadata.
A7: #ERR: async rejected | B7: =meta!B13("async rejected") | C7: async | D7: TRUE | E7: Simulated promise is rejected.
A8: #ERR: io not found | B8: =meta!B13("io not found") | C8: io | D8: TRUE | E8: Pure IO simulation has no matching fixture row.

Sheet runtime_io
A1: id | B1: kind | C1: key | D1: payload | E1: exists | F1: notes
A2: file:readme | B2: file | C2: /workspace/README.md | D2: Bun workbook runtime fixture | E2: TRUE | F2: pure fs.readFile simulation
A3: process:cwd | B3: process | C3: cwd | D3: /Users/a.mametyev/PycharmProjects/bun | E3: TRUE | F3: process.cwd simulation
A4: network:example | B4: network | C4: https://example.test/hello | D4: {"status":200,"body":"hello"} | E4: TRUE | F4: network.fetch simulation

Sheet runtime_async
A1: promise_id | B1: constructor | C1: state | D1: value | E1: reason | F1: state_envelope | G1: value_envelope
A2: p1 | B2: promise.resolve("ok") | C2: RESOLVED | D2: ok | F2: =meta!B12(C2) | G2: =meta!B12(D2)
A3: p2 | B3: promise.reject("fail") | C3: REJECTED | E3: fail | F3: =meta!B12(C3) | G3: =meta!B13("async rejected",E3)

Sheet runtime_values
A1: case | B1: expr | C1: typed_env | D1: type | E1: unwrapped | F1: is_error | G1: error_code | H1: expected | I1: pass
A2: =IF(tests!A2="","",tests!A2) | B2: =IF(A2="","",tests!B2) | C2: =IF(A2="","",meta!B9(B2)) | D2: =IF(A2="","",meta!B15(C2)) | E2: =IF(A2="","",meta!B14(C2)) | F2: =IF(A2="","",meta!B17(C2)) | G2: =IF(A2="","",meta!B16(C2)) | H2: =IF(A2="","",tests!D2) | I2: =IF(A2="","",IFERROR(E2=H2,FALSE))
A3: =IF(tests!A3="","",tests!A3) | B3: =IF(A3="","",tests!B3) | C3: =IF(A3="","",meta!B9(B3)) | D3: =IF(A3="","",meta!B15(C3)) | E3: =IF(A3="","",meta!B14(C3)) | F3: =IF(A3="","",meta!B17(C3)) | G3: =IF(A3="","",meta!B16(C3)) | H3: =IF(A3="","",tests!D3) | I3: =IF(A3="","",IFERROR(E3=H3,FALSE))
A4: =IF(tests!A4="","",tests!A4) | B4: =IF(A4="","",tests!B4) | C4: =IF(A4="","",meta!B9(B4)) | D4: =IF(A4="","",meta!B15(C4)) | E4: =IF(A4="","",meta!B14(C4)) | F4: =IF(A4="","",meta!B17(C4)) | G4: =IF(A4="","",meta!B16(C4)) | H4: =IF(A4="","",tests!D4) | I4: =IF(A4="","",IFERROR(E4=H4,FALSE))
A5: =IF(tests!A5="","",tests!A5) | B5: =IF(A5="","",tests!B5) | C5: =IF(A5="","",meta!B9(B5)) | D5: =IF(A5="","",meta!B15(C5)) | E5: =IF(A5="","",meta!B14(C5)) | F5: =IF(A5="","",meta!B17(C5)) | G5: =IF(A5="","",meta!B16(C5)) | H5: =IF(A5="","",tests!D5) | I5: =IF(A5="","",IFERROR(E5=H5,FALSE))
A6: =IF(tests!A6="","",tests!A6) | B6: =IF(A6="","",tests!B6) | C6: =IF(A6="","",meta!B9(B6)) | D6: =IF(A6="","",meta!B15(C6)) | E6: =IF(A6="","",meta!B14(C6)) | F6: =IF(A6="","",meta!B17(C6)) | G6: =IF(A6="","",meta!B16(C6)) | H6: =IF(A6="","",tests!D6) | I6: =IF(A6="","",IFERROR(E6=H6,FALSE))
A7: =IF(tests!A7="","",tests!A7) | B7: =IF(A7="","",tests!B7) | C7: =IF(A7="","",meta!B9(B7)) | D7: =IF(A7="","",meta!B15(C7)) | E7: =IF(A7="","",meta!B14(C7)) | F7: =IF(A7="","",meta!B17(C7)) | G7: =IF(A7="","",meta!B16(C7)) | H7: =IF(A7="","",tests!D7) | I7: =IF(A7="","",IFERROR(E7=H7,FALSE))
A8: =IF(tests!A8="","",tests!A8) | B8: =IF(A8="","",tests!B8) | C8: =IF(A8="","",meta!B9(B8)) | D8: =IF(A8="","",meta!B15(C8)) | E8: =IF(A8="","",meta!B14(C8)) | F8: =IF(A8="","",meta!B17(C8)) | G8: =IF(A8="","",meta!B16(C8)) | H8: =IF(A8="","",tests!D8) | I8: =IF(A8="","",IFERROR(E8=H8,FALSE))
A9: =IF(tests!A9="","",tests!A9) | B9: =IF(A9="","",tests!B9) | C9: =IF(A9="","",meta!B9(B9)) | D9: =IF(A9="","",meta!B15(C9)) | E9: =IF(A9="","",meta!B14(C9)) | F9: =IF(A9="","",meta!B17(C9)) | G9: =IF(A9="","",meta!B16(C9)) | H9: =IF(A9="","",tests!D9) | I9: =IF(A9="","",IFERROR(E9=H9,FALSE))
A10: =IF(tests!A10="","",tests!A10) | B10: =IF(A10="","",tests!B10) | C10: =IF(A10="","",meta!B9(B10)) | D10: =IF(A10="","",meta!B15(C10)) | E10: =IF(A10="","",meta!B14(C10)) | F10: =IF(A10="","",meta!B17(C10)) | G10: =IF(A10="","",meta!B16(C10)) | H10: =IF(A10="","",tests!D10) | I10: =IF(A10="","",IFERROR(E10=H10,FALSE))
A11: =IF(tests!A11="","",tests!A11) | B11: =IF(A11="","",tests!B11) | C11: =IF(A11="","",meta!B9(B11)) | D11: =IF(A11="","",meta!B15(C11)) | E11: =IF(A11="","",meta!B14(C11)) | F11: =IF(A11="","",meta!B17(C11)) | G11: =IF(A11="","",meta!B16(C11)) | H11: =IF(A11="","",tests!D11) | I11: =IF(A11="","",IFERROR(E11=H11,FALSE))
A12: =IF(tests!A12="","",tests!A12) | B12: =IF(A12="","",tests!B12) | C12: =IF(A12="","",meta!B9(B12)) | D12: =IF(A12="","",meta!B15(C12)) | E12: =IF(A12="","",meta!B14(C12)) | F12: =IF(A12="","",meta!B17(C12)) | G12: =IF(A12="","",meta!B16(C12)) | H12: =IF(A12="","",tests!D12) | I12: =IF(A12="","",IFERROR(E12=H12,FALSE))
A13: =IF(tests!A13="","",tests!A13) | B13: =IF(A13="","",tests!B13) | C13: =IF(A13="","",meta!B9(B13)) | D13: =IF(A13="","",meta!B15(C13)) | E13: =IF(A13="","",meta!B14(C13)) | F13: =IF(A13="","",meta!B17(C13)) | G13: =IF(A13="","",meta!B16(C13)) | H13: =IF(A13="","",tests!D13) | I13: =IF(A13="","",IFERROR(E13=H13,FALSE))
... A23: =IF(tests!A23="","",tests!A23) | B23: =IF(A23="","",tests!B23) | C23: =IF(A23="","",meta!B9(B23)) | D23: =IF(A23="","",meta!B15(C23)) | E23: =IF(A23="","",meta!B14(C23)) | F23: =IF(A23="","",meta!B17(C23)) | G23: =IF(A23="","",meta!B16(C23)) | H23: =IF(A23="","",tests!D23) | I23: =IF(A23="","",IFERROR(E23=H23,FALSE))

Sheet runtime_frames
A1: frame_id | B1: test_case | C1: parent_id | D1: phase | E1: depth_estimate | F1: expr | G1: parsed_module | H1: parsed_fn | I1: arg_count | J1: typed_result | K1: unwrapped_result | L1: status | M1: budget_remaining
A2: =IF(tests!A2="","","F"&TEXT(ROW()-1,"000")) | B2: =IF(A2="","",tests!A2) | C2: ROOT | D2: eval | E2: =IF(A2="","",LEN(F2)-LEN(SUBSTITUTE(F2,"(",""))) | F2: =IF(A2="","",tests!B2) | G2: =IF(A2="","",INDEX(meta!B7(F2),1)) | H2: =IF(A2="","",INDEX(meta!B7(F2),2)) | I2: =IF(A2="","",IFERROR(INDEX(meta!B7(F2),3),"")) | J2: =IF(A2="","",meta!B9(F2)) | K2: =IF(A2="","",meta!B14(J2)) | L2: =IF(A2="","",IF(meta!B17(J2),"ERR","OK")) | M2: =IF(A2="","",64-E2)
A3: =IF(tests!A3="","","F"&TEXT(ROW()-1,"000")) | B3: =IF(A3="","",tests!A3) | C3: ROOT | D3: eval | E3: =IF(A3="","",LEN(F3)-LEN(SUBSTITUTE(F3,"(",""))) | F3: =IF(A3="","",tests!B3) | G3: =IF(A3="","",INDEX(meta!B7(F3),1)) | H3: =IF(A3="","",INDEX(meta!B7(F3),2)) | I3: =IF(A3="","",IFERROR(INDEX(meta!B7(F3),3),"")) | J3: =IF(A3="","",meta!B9(F3)) | K3: =IF(A3="","",meta!B14(J3)) | L3: =IF(A3="","",IF(meta!B17(J3),"ERR","OK")) | M3: =IF(A3="","",64-E3)
A4: =IF(tests!A4="","","F"&TEXT(ROW()-1,"000")) | B4: =IF(A4="","",tests!A4) | C4: ROOT | D4: eval | E4: =IF(A4="","",LEN(F4)-LEN(SUBSTITUTE(F4,"(",""))) | F4: =IF(A4="","",tests!B4) | G4: =IF(A4="","",INDEX(meta!B7(F4),1)) | H4: =IF(A4="","",INDEX(meta!B7(F4),2)) | I4: =IF(A4="","",IFERROR(INDEX(meta!B7(F4),3),"")) | J4: =IF(A4="","",meta!B9(F4)) | K4: =IF(A4="","",meta!B14(J4)) | L4: =IF(A4="","",IF(meta!B17(J4),"ERR","OK")) | M4: =IF(A4="","",64-E4)
A5: =IF(tests!A5="","","F"&TEXT(ROW()-1,"000")) | B5: =IF(A5="","",tests!A5) | C5: ROOT | D5: eval | E5: =IF(A5="","",LEN(F5)-LEN(SUBSTITUTE(F5,"(",""))) | F5: =IF(A5="","",tests!B5) | G5: =IF(A5="","",INDEX(meta!B7(F5),1)) | H5: =IF(A5="","",INDEX(meta!B7(F5),2)) | I5: =IF(A5="","",IFERROR(INDEX(meta!B7(F5),3),"")) | J5: =IF(A5="","",meta!B9(F5)) | K5: =IF(A5="","",meta!B14(J5)) | L5: =IF(A5="","",IF(meta!B17(J5),"ERR","OK")) | M5: =IF(A5="","",64-E5)
A6: =IF(tests!A6="","","F"&TEXT(ROW()-1,"000")) | B6: =IF(A6="","",tests!A6) | C6: ROOT | D6: eval | E6: =IF(A6="","",LEN(F6)-LEN(SUBSTITUTE(F6,"(",""))) | F6: =IF(A6="","",tests!B6) | G6: =IF(A6="","",INDEX(meta!B7(F6),1)) | H6: =IF(A6="","",INDEX(meta!B7(F6),2)) | I6: =IF(A6="","",IFERROR(INDEX(meta!B7(F6),3),"")) | J6: =IF(A6="","",meta!B9(F6)) | K6: =IF(A6="","",meta!B14(J6)) | L6: =IF(A6="","",IF(meta!B17(J6),"ERR","OK")) | M6: =IF(A6="","",64-E6)
A7: =IF(tests!A7="","","F"&TEXT(ROW()-1,"000")) | B7: =IF(A7="","",tests!A7) | C7: ROOT | D7: eval | E7: =IF(A7="","",LEN(F7)-LEN(SUBSTITUTE(F7,"(",""))) | F7: =IF(A7="","",tests!B7) | G7: =IF(A7="","",INDEX(meta!B7(F7),1)) | H7: =IF(A7="","",INDEX(meta!B7(F7),2)) | I7: =IF(A7="","",IFERROR(INDEX(meta!B7(F7),3),"")) | J7: =IF(A7="","",meta!B9(F7)) | K7: =IF(A7="","",meta!B14(J7)) | L7: =IF(A7="","",IF(meta!B17(J7),"ERR","OK")) | M7: =IF(A7="","",64-E7)
A8: =IF(tests!A8="","","F"&TEXT(ROW()-1,"000")) | B8: =IF(A8="","",tests!A8) | C8: ROOT | D8: eval | E8: =IF(A8="","",LEN(F8)-LEN(SUBSTITUTE(F8,"(",""))) | F8: =IF(A8="","",tests!B8) | G8: =IF(A8="","",INDEX(meta!B7(F8),1)) | H8: =IF(A8="","",INDEX(meta!B7(F8),2)) | I8: =IF(A8="","",IFERROR(INDEX(meta!B7(F8),3),"")) | J8: =IF(A8="","",meta!B9(F8)) | K8: =IF(A8="","",meta!B14(J8)) | L8: =IF(A8="","",IF(meta!B17(J8),"ERR","OK")) | M8: =IF(A8="","",64-E8)
A9: =IF(tests!A9="","","F"&TEXT(ROW()-1,"000")) | B9: =IF(A9="","",tests!A9) | C9: ROOT | D9: eval | E9: =IF(A9="","",LEN(F9)-LEN(SUBSTITUTE(F9,"(",""))) | F9: =IF(A9="","",tests!B9) | G9: =IF(A9="","",INDEX(meta!B7(F9),1)) | H9: =IF(A9="","",INDEX(meta!B7(F9),2)) | I9: =IF(A9="","",IFERROR(INDEX(meta!B7(F9),3),"")) | J9: =IF(A9="","",meta!B9(F9)) | K9: =IF(A9="","",meta!B14(J9)) | L9: =IF(A9="","",IF(meta!B17(J9),"ERR","OK")) | M9: =IF(A9="","",64-E9)
A10: =IF(tests!A10="","","F"&TEXT(ROW()-1,"000")) | B10: =IF(A10="","",tests!A10) | C10: ROOT | D10: eval | E10: =IF(A10="","",LEN(F10)-LEN(SUBSTITUTE(F10,"(",""))) | F10: =IF(A10="","",tests!B10) | G10: =IF(A10="","",INDEX(meta!B7(F10),1)) | H10: =IF(A10="","",INDEX(meta!B7(F10),2)) | I10: =IF(A10="","",IFERROR(INDEX(meta!B7(F10),3),"")) | J10: =IF(A10="","",meta!B9(F10)) | K10: =IF(A10="","",meta!B14(J10)) | L10: =IF(A10="","",IF(meta!B17(J10),"ERR","OK")) | M10: =IF(A10="","",64-E10)
A11: =IF(tests!A11="","","F"&TEXT(ROW()-1,"000")) | B11: =IF(A11="","",tests!A11) | C11: ROOT | D11: eval | E11: =IF(A11="","",LEN(F11)-LEN(SUBSTITUTE(F11,"(",""))) | F11: =IF(A11="","",tests!B11) | G11: =IF(A11="","",INDEX(meta!B7(F11),1)) | H11: =IF(A11="","",INDEX(meta!B7(F11),2)) | I11: =IF(A11="","",IFERROR(INDEX(meta!B7(F11),3),"")) | J11: =IF(A11="","",meta!B9(F11)) | K11: =IF(A11="","",meta!B14(J11)) | L11: =IF(A11="","",IF(meta!B17(J11),"ERR","OK")) | M11: =IF(A11="","",64-E11)
A12: =IF(tests!A12="","","F"&TEXT(ROW()-1,"000")) | B12: =IF(A12="","",tests!A12) | C12: ROOT | D12: eval | E12: =IF(A12="","",LEN(F12)-LEN(SUBSTITUTE(F12,"(",""))) | F12: =IF(A12="","",tests!B12) | G12: =IF(A12="","",INDEX(meta!B7(F12),1)) | H12: =IF(A12="","",INDEX(meta!B7(F12),2)) | I12: =IF(A12="","",IFERROR(INDEX(meta!B7(F12),3),"")) | J12: =IF(A12="","",meta!B9(F12)) | K12: =IF(A12="","",meta!B14(J12)) | L12: =IF(A12="","",IF(meta!B17(J12),"ERR","OK")) | M12: =IF(A12="","",64-E12)
A13: =IF(tests!A13="","","F"&TEXT(ROW()-1,"000")) | B13: =IF(A13="","",tests!A13) | C13: ROOT | D13: eval | E13: =IF(A13="","",LEN(F13)-LEN(SUBSTITUTE(F13,"(",""))) | F13: =IF(A13="","",tests!B13) | G13: =IF(A13="","",INDEX(meta!B7(F13),1)) | H13: =IF(A13="","",INDEX(meta!B7(F13),2)) | I13: =IF(A13="","",IFERROR(INDEX(meta!B7(F13),3),"")) | J13: =IF(A13="","",meta!B9(F13)) | K13: =IF(A13="","",meta!B14(J13)) | L13: =IF(A13="","",IF(meta!B17(J13),"ERR","OK")) | M13: =IF(A13="","",64-E13)
... A23: =IF(tests!A23="","","F"&TEXT(ROW()-1,"000")) | B23: =IF(A23="","",tests!A23) | C23: ROOT | D23: eval | E23: =IF(A23="","",LEN(F23)-LEN(SUBSTITUTE(F23,"(",""))) | F23: =IF(A23="","",tests!B23) | G23: =IF(A23="","",INDEX(meta!B7(F23),1)) | H23: =IF(A23="","",INDEX(meta!B7(F23),2)) | I23: =IF(A23="","",IFERROR(INDEX(meta!B7(F23),3),"")) | J23: =IF(A23="","",meta!B9(F23)) | K23: =IF(A23="","",meta!B14(J23)) | L23: =IF(A23="","",IF(meta!B17(J23),"ERR","OK")) | M23: =IF(A23="","",64-E23)
